2025-03-10 13:23:32,278 - INFO - logging in using static token
2025-03-10 13:23:33,297 - INFO - Shard ID None has connected to Gateway (Session ID: 4a096552d2cde11c24eee67ba75c184d).
2025-03-10 13:23:35,307 - INFO - Logged in as anti-yappinator#0972 (ID: 1346984198023680121)
2025-03-10 13:23:35,308 - INFO - Connected to guild: Testing Server (ID: 1346987972121071739)
2025-03-10 13:30:28,308 - INFO - logging in using static token
2025-03-10 13:30:29,313 - INFO - Shard ID None has connected to Gateway (Session ID: 8b8f3abf9b5e502f8b21a092cbaa065f).
2025-03-10 13:30:31,323 - INFO - Logged in as anti-yappinator#0972 (ID: 1346984198023680121)
2025-03-10 13:30:31,323 - INFO - Connected to guild: Testing Server (ID: 1346987972121071739)
2025-03-10 18:07:04,961 - WARNING - Shard ID None has stopped responding to the gateway. Closing and restarting.
2025-03-10 18:07:05,147 - ERROR - Attempting a reconnect in 0.89s
Traceback (most recent call last):
  File "C:\Users\Merlyn\AppData\Local\Programs\Python\Python313\Lib\site-packages\aiohttp\connector.py", line 1362, in _create_direct_connection
    hosts = await self._resolve_host(host, port, traces=traces)
            ^^^^^^^^^^^^^^^^^^^^^^^^^^^^^^^^^^^^^^^^^^^^^^^^^^^
  File "C:\Users\Merlyn\AppData\Local\Programs\Python\Python313\Lib\site-packages\aiohttp\connector.py", line 995, in _resolve_host
    return await asyncio.shield(resolved_host_task)
           ^^^^^^^^^^^^^^^^^^^^^^^^^^^^^^^^^^^^^^^^
  File "C:\Users\Merlyn\AppData\Local\Programs\Python\Python313\Lib\site-packages\aiohttp\connector.py", line 1026, in _resolve_host_with_throttle
    addrs = await self._resolver.resolve(host, port, family=self._family)
            ^^^^^^^^^^^^^^^^^^^^^^^^^^^^^^^^^^^^^^^^^^^^^^^^^^^^^^^^^^^^^
  File "C:\Users\Merlyn\AppData\Local\Programs\Python\Python313\Lib\site-packages\aiohttp\resolver.py", line 36, in resolve
    infos = await self._loop.getaddrinfo(
            ^^^^^^^^^^^^^^^^^^^^^^^^^^^^^
    ...<5 lines>...
    )
    ^
  File "C:\Users\Merlyn\AppData\Local\Programs\Python\Python313\Lib\asyncio\base_events.py", line 934, in getaddrinfo
    return await self.run_in_executor(
           ^^^^^^^^^^^^^^^^^^^^^^^^^^^
        None, getaddr_func, host, port, family, type, proto, flags)
        ^^^^^^^^^^^^^^^^^^^^^^^^^^^^^^^^^^^^^^^^^^^^^^^^^^^^^^^^^^^
  File "C:\Users\Merlyn\AppData\Local\Programs\Python\Python313\Lib\concurrent\futures\thread.py", line 59, in run
    result = self.fn(*self.args, **self.kwargs)
  File "C:\Users\Merlyn\AppData\Local\Programs\Python\Python313\Lib\socket.py", line 975, in getaddrinfo
    for res in _socket.getaddrinfo(host, port, family, type, proto, flags):
               ~~~~~~~~~~~~~~~~~~~^^^^^^^^^^^^^^^^^^^^^^^^^^^^^^^^^^^^^^^^
socket.gaierror: [Errno 11001] getaddrinfo failed

The above exception was the direct cause of the following exception:

Traceback (most recent call last):
  File "C:\Users\Merlyn\AppData\Local\Programs\Python\Python313\Lib\site-packages\discord\client.py", line 701, in connect
    self.ws = await asyncio.wait_for(coro, timeout=60.0)
              ^^^^^^^^^^^^^^^^^^^^^^^^^^^^^^^^^^^^^^^^^^
  File "C:\Users\Merlyn\AppData\Local\Programs\Python\Python313\Lib\asyncio\tasks.py", line 507, in wait_for
    return await fut
           ^^^^^^^^^
  File "C:\Users\Merlyn\AppData\Local\Programs\Python\Python313\Lib\site-packages\discord\gateway.py", line 375, in from_client
    socket = await client.http.ws_connect(str(url))
             ^^^^^^^^^^^^^^^^^^^^^^^^^^^^^^^^^^^^^^
  File "C:\Users\Merlyn\AppData\Local\Programs\Python\Python313\Lib\site-packages\discord\http.py", line 554, in ws_connect
    return await self.__session.ws_connect(url, **kwargs)
           ^^^^^^^^^^^^^^^^^^^^^^^^^^^^^^^^^^^^^^^^^^^^^^
  File "C:\Users\Merlyn\AppData\Local\Programs\Python\Python313\Lib\site-packages\aiohttp\client.py", line 1004, in _ws_connect
    resp = await self.request(
           ^^^^^^^^^^^^^^^^^^^
    ...<11 lines>...
    )
    ^
  File "C:\Users\Merlyn\AppData\Local\Programs\Python\Python313\Lib\site-packages\aiohttp\client.py", line 703, in _request
    conn = await self._connector.connect(
           ^^^^^^^^^^^^^^^^^^^^^^^^^^^^^^
        req, traces=traces, timeout=real_timeout
        ^^^^^^^^^^^^^^^^^^^^^^^^^^^^^^^^^^^^^^^^
    )
    ^
  File "C:\Users\Merlyn\AppData\Local\Programs\Python\Python313\Lib\site-packages\aiohttp\connector.py", line 548, in connect
    proto = await self._create_connection(req, traces, timeout)
            ^^^^^^^^^^^^^^^^^^^^^^^^^^^^^^^^^^^^^^^^^^^^^^^^^^^
  File "C:\Users\Merlyn\AppData\Local\Programs\Python\Python313\Lib\site-packages\aiohttp\connector.py", line 1056, in _create_connection
    _, proto = await self._create_direct_connection(req, traces, timeout)
               ^^^^^^^^^^^^^^^^^^^^^^^^^^^^^^^^^^^^^^^^^^^^^^^^^^^^^^^^^^
  File "C:\Users\Merlyn\AppData\Local\Programs\Python\Python313\Lib\site-packages\aiohttp\connector.py", line 1368, in _create_direct_connection
    raise ClientConnectorDNSError(req.connection_key, exc) from exc
aiohttp.client_exceptions.ClientConnectorDNSError: Cannot connect to host gateway-us-east1-c.discord.gg:443 ssl:default [getaddrinfo failed]
2025-03-10 18:07:06,471 - ERROR - Attempting a reconnect in 1.58s
Traceback (most recent call last):
  File "C:\Users\Merlyn\AppData\Local\Programs\Python\Python313\Lib\site-packages\aiohttp\connector.py", line 1362, in _create_direct_connection
    hosts = await self._resolve_host(host, port, traces=traces)
            ^^^^^^^^^^^^^^^^^^^^^^^^^^^^^^^^^^^^^^^^^^^^^^^^^^^
  File "C:\Users\Merlyn\AppData\Local\Programs\Python\Python313\Lib\site-packages\aiohttp\connector.py", line 995, in _resolve_host
    return await asyncio.shield(resolved_host_task)
           ^^^^^^^^^^^^^^^^^^^^^^^^^^^^^^^^^^^^^^^^
  File "C:\Users\Merlyn\AppData\Local\Programs\Python\Python313\Lib\site-packages\aiohttp\connector.py", line 1026, in _resolve_host_with_throttle
    addrs = await self._resolver.resolve(host, port, family=self._family)
            ^^^^^^^^^^^^^^^^^^^^^^^^^^^^^^^^^^^^^^^^^^^^^^^^^^^^^^^^^^^^^
  File "C:\Users\Merlyn\AppData\Local\Programs\Python\Python313\Lib\site-packages\aiohttp\resolver.py", line 36, in resolve
    infos = await self._loop.getaddrinfo(
            ^^^^^^^^^^^^^^^^^^^^^^^^^^^^^
    ...<5 lines>...
    )
    ^
  File "C:\Users\Merlyn\AppData\Local\Programs\Python\Python313\Lib\asyncio\base_events.py", line 934, in getaddrinfo
    return await self.run_in_executor(
           ^^^^^^^^^^^^^^^^^^^^^^^^^^^
        None, getaddr_func, host, port, family, type, proto, flags)
        ^^^^^^^^^^^^^^^^^^^^^^^^^^^^^^^^^^^^^^^^^^^^^^^^^^^^^^^^^^^
  File "C:\Users\Merlyn\AppData\Local\Programs\Python\Python313\Lib\concurrent\futures\thread.py", line 59, in run
    result = self.fn(*self.args, **self.kwargs)
  File "C:\Users\Merlyn\AppData\Local\Programs\Python\Python313\Lib\socket.py", line 975, in getaddrinfo
    for res in _socket.getaddrinfo(host, port, family, type, proto, flags):
               ~~~~~~~~~~~~~~~~~~~^^^^^^^^^^^^^^^^^^^^^^^^^^^^^^^^^^^^^^^^
socket.gaierror: [Errno 11001] getaddrinfo failed

The above exception was the direct cause of the following exception:

Traceback (most recent call last):
  File "C:\Users\Merlyn\AppData\Local\Programs\Python\Python313\Lib\site-packages\discord\client.py", line 701, in connect
    self.ws = await asyncio.wait_for(coro, timeout=60.0)
              ^^^^^^^^^^^^^^^^^^^^^^^^^^^^^^^^^^^^^^^^^^
  File "C:\Users\Merlyn\AppData\Local\Programs\Python\Python313\Lib\asyncio\tasks.py", line 507, in wait_for
    return await fut
           ^^^^^^^^^
  File "C:\Users\Merlyn\AppData\Local\Programs\Python\Python313\Lib\site-packages\discord\gateway.py", line 375, in from_client
    socket = await client.http.ws_connect(str(url))
             ^^^^^^^^^^^^^^^^^^^^^^^^^^^^^^^^^^^^^^
  File "C:\Users\Merlyn\AppData\Local\Programs\Python\Python313\Lib\site-packages\discord\http.py", line 554, in ws_connect
    return await self.__session.ws_connect(url, **kwargs)
           ^^^^^^^^^^^^^^^^^^^^^^^^^^^^^^^^^^^^^^^^^^^^^^
  File "C:\Users\Merlyn\AppData\Local\Programs\Python\Python313\Lib\site-packages\aiohttp\client.py", line 1004, in _ws_connect
    resp = await self.request(
           ^^^^^^^^^^^^^^^^^^^
    ...<11 lines>...
    )
    ^
  File "C:\Users\Merlyn\AppData\Local\Programs\Python\Python313\Lib\site-packages\aiohttp\client.py", line 703, in _request
    conn = await self._connector.connect(
           ^^^^^^^^^^^^^^^^^^^^^^^^^^^^^^
        req, traces=traces, timeout=real_timeout
        ^^^^^^^^^^^^^^^^^^^^^^^^^^^^^^^^^^^^^^^^
    )
    ^
  File "C:\Users\Merlyn\AppData\Local\Programs\Python\Python313\Lib\site-packages\aiohttp\connector.py", line 548, in connect
    proto = await self._create_connection(req, traces, timeout)
            ^^^^^^^^^^^^^^^^^^^^^^^^^^^^^^^^^^^^^^^^^^^^^^^^^^^
  File "C:\Users\Merlyn\AppData\Local\Programs\Python\Python313\Lib\site-packages\aiohttp\connector.py", line 1056, in _create_connection
    _, proto = await self._create_direct_connection(req, traces, timeout)
               ^^^^^^^^^^^^^^^^^^^^^^^^^^^^^^^^^^^^^^^^^^^^^^^^^^^^^^^^^^
  File "C:\Users\Merlyn\AppData\Local\Programs\Python\Python313\Lib\site-packages\aiohttp\connector.py", line 1368, in _create_direct_connection
    raise ClientConnectorDNSError(req.connection_key, exc) from exc
aiohttp.client_exceptions.ClientConnectorDNSError: Cannot connect to host gateway-us-east1-c.discord.gg:443 ssl:default [getaddrinfo failed]
2025-03-10 18:07:08,130 - ERROR - Attempting a reconnect in 4.45s
Traceback (most recent call last):
  File "C:\Users\Merlyn\AppData\Local\Programs\Python\Python313\Lib\site-packages\aiohttp\connector.py", line 1362, in _create_direct_connection
    hosts = await self._resolve_host(host, port, traces=traces)
            ^^^^^^^^^^^^^^^^^^^^^^^^^^^^^^^^^^^^^^^^^^^^^^^^^^^
  File "C:\Users\Merlyn\AppData\Local\Programs\Python\Python313\Lib\site-packages\aiohttp\connector.py", line 995, in _resolve_host
    return await asyncio.shield(resolved_host_task)
           ^^^^^^^^^^^^^^^^^^^^^^^^^^^^^^^^^^^^^^^^
  File "C:\Users\Merlyn\AppData\Local\Programs\Python\Python313\Lib\site-packages\aiohttp\connector.py", line 1026, in _resolve_host_with_throttle
    addrs = await self._resolver.resolve(host, port, family=self._family)
            ^^^^^^^^^^^^^^^^^^^^^^^^^^^^^^^^^^^^^^^^^^^^^^^^^^^^^^^^^^^^^
  File "C:\Users\Merlyn\AppData\Local\Programs\Python\Python313\Lib\site-packages\aiohttp\resolver.py", line 36, in resolve
    infos = await self._loop.getaddrinfo(
            ^^^^^^^^^^^^^^^^^^^^^^^^^^^^^
    ...<5 lines>...
    )
    ^
  File "C:\Users\Merlyn\AppData\Local\Programs\Python\Python313\Lib\asyncio\base_events.py", line 934, in getaddrinfo
    return await self.run_in_executor(
           ^^^^^^^^^^^^^^^^^^^^^^^^^^^
        None, getaddr_func, host, port, family, type, proto, flags)
        ^^^^^^^^^^^^^^^^^^^^^^^^^^^^^^^^^^^^^^^^^^^^^^^^^^^^^^^^^^^
  File "C:\Users\Merlyn\AppData\Local\Programs\Python\Python313\Lib\concurrent\futures\thread.py", line 59, in run
    result = self.fn(*self.args, **self.kwargs)
  File "C:\Users\Merlyn\AppData\Local\Programs\Python\Python313\Lib\socket.py", line 975, in getaddrinfo
    for res in _socket.getaddrinfo(host, port, family, type, proto, flags):
               ~~~~~~~~~~~~~~~~~~~^^^^^^^^^^^^^^^^^^^^^^^^^^^^^^^^^^^^^^^^
socket.gaierror: [Errno 11001] getaddrinfo failed

The above exception was the direct cause of the following exception:

Traceback (most recent call last):
  File "C:\Users\Merlyn\AppData\Local\Programs\Python\Python313\Lib\site-packages\discord\client.py", line 701, in connect
    self.ws = await asyncio.wait_for(coro, timeout=60.0)
              ^^^^^^^^^^^^^^^^^^^^^^^^^^^^^^^^^^^^^^^^^^
  File "C:\Users\Merlyn\AppData\Local\Programs\Python\Python313\Lib\asyncio\tasks.py", line 507, in wait_for
    return await fut
           ^^^^^^^^^
  File "C:\Users\Merlyn\AppData\Local\Programs\Python\Python313\Lib\site-packages\discord\gateway.py", line 375, in from_client
    socket = await client.http.ws_connect(str(url))
             ^^^^^^^^^^^^^^^^^^^^^^^^^^^^^^^^^^^^^^
  File "C:\Users\Merlyn\AppData\Local\Programs\Python\Python313\Lib\site-packages\discord\http.py", line 554, in ws_connect
    return await self.__session.ws_connect(url, **kwargs)
           ^^^^^^^^^^^^^^^^^^^^^^^^^^^^^^^^^^^^^^^^^^^^^^
  File "C:\Users\Merlyn\AppData\Local\Programs\Python\Python313\Lib\site-packages\aiohttp\client.py", line 1004, in _ws_connect
    resp = await self.request(
           ^^^^^^^^^^^^^^^^^^^
    ...<11 lines>...
    )
    ^
  File "C:\Users\Merlyn\AppData\Local\Programs\Python\Python313\Lib\site-packages\aiohttp\client.py", line 703, in _request
    conn = await self._connector.connect(
           ^^^^^^^^^^^^^^^^^^^^^^^^^^^^^^
        req, traces=traces, timeout=real_timeout
        ^^^^^^^^^^^^^^^^^^^^^^^^^^^^^^^^^^^^^^^^
    )
    ^
  File "C:\Users\Merlyn\AppData\Local\Programs\Python\Python313\Lib\site-packages\aiohttp\connector.py", line 548, in connect
    proto = await self._create_connection(req, traces, timeout)
            ^^^^^^^^^^^^^^^^^^^^^^^^^^^^^^^^^^^^^^^^^^^^^^^^^^^
  File "C:\Users\Merlyn\AppData\Local\Programs\Python\Python313\Lib\site-packages\aiohttp\connector.py", line 1056, in _create_connection
    _, proto = await self._create_direct_connection(req, traces, timeout)
               ^^^^^^^^^^^^^^^^^^^^^^^^^^^^^^^^^^^^^^^^^^^^^^^^^^^^^^^^^^
  File "C:\Users\Merlyn\AppData\Local\Programs\Python\Python313\Lib\site-packages\aiohttp\connector.py", line 1368, in _create_direct_connection
    raise ClientConnectorDNSError(req.connection_key, exc) from exc
aiohttp.client_exceptions.ClientConnectorDNSError: Cannot connect to host gateway-us-east1-c.discord.gg:443 ssl:default [getaddrinfo failed]
2025-03-10 18:07:12,673 - ERROR - Attempting a reconnect in 13.48s
Traceback (most recent call last):
  File "C:\Users\Merlyn\AppData\Local\Programs\Python\Python313\Lib\site-packages\aiohttp\connector.py", line 1362, in _create_direct_connection
    hosts = await self._resolve_host(host, port, traces=traces)
            ^^^^^^^^^^^^^^^^^^^^^^^^^^^^^^^^^^^^^^^^^^^^^^^^^^^
  File "C:\Users\Merlyn\AppData\Local\Programs\Python\Python313\Lib\site-packages\aiohttp\connector.py", line 995, in _resolve_host
    return await asyncio.shield(resolved_host_task)
           ^^^^^^^^^^^^^^^^^^^^^^^^^^^^^^^^^^^^^^^^
  File "C:\Users\Merlyn\AppData\Local\Programs\Python\Python313\Lib\site-packages\aiohttp\connector.py", line 1026, in _resolve_host_with_throttle
    addrs = await self._resolver.resolve(host, port, family=self._family)
            ^^^^^^^^^^^^^^^^^^^^^^^^^^^^^^^^^^^^^^^^^^^^^^^^^^^^^^^^^^^^^
  File "C:\Users\Merlyn\AppData\Local\Programs\Python\Python313\Lib\site-packages\aiohttp\resolver.py", line 36, in resolve
    infos = await self._loop.getaddrinfo(
            ^^^^^^^^^^^^^^^^^^^^^^^^^^^^^
    ...<5 lines>...
    )
    ^
  File "C:\Users\Merlyn\AppData\Local\Programs\Python\Python313\Lib\asyncio\base_events.py", line 934, in getaddrinfo
    return await self.run_in_executor(
           ^^^^^^^^^^^^^^^^^^^^^^^^^^^
        None, getaddr_func, host, port, family, type, proto, flags)
        ^^^^^^^^^^^^^^^^^^^^^^^^^^^^^^^^^^^^^^^^^^^^^^^^^^^^^^^^^^^
  File "C:\Users\Merlyn\AppData\Local\Programs\Python\Python313\Lib\concurrent\futures\thread.py", line 59, in run
    result = self.fn(*self.args, **self.kwargs)
  File "C:\Users\Merlyn\AppData\Local\Programs\Python\Python313\Lib\socket.py", line 975, in getaddrinfo
    for res in _socket.getaddrinfo(host, port, family, type, proto, flags):
               ~~~~~~~~~~~~~~~~~~~^^^^^^^^^^^^^^^^^^^^^^^^^^^^^^^^^^^^^^^^
socket.gaierror: [Errno 11001] getaddrinfo failed

The above exception was the direct cause of the following exception:

Traceback (most recent call last):
  File "C:\Users\Merlyn\AppData\Local\Programs\Python\Python313\Lib\site-packages\discord\client.py", line 701, in connect
    self.ws = await asyncio.wait_for(coro, timeout=60.0)
              ^^^^^^^^^^^^^^^^^^^^^^^^^^^^^^^^^^^^^^^^^^
  File "C:\Users\Merlyn\AppData\Local\Programs\Python\Python313\Lib\asyncio\tasks.py", line 507, in wait_for
    return await fut
           ^^^^^^^^^
  File "C:\Users\Merlyn\AppData\Local\Programs\Python\Python313\Lib\site-packages\discord\gateway.py", line 375, in from_client
    socket = await client.http.ws_connect(str(url))
             ^^^^^^^^^^^^^^^^^^^^^^^^^^^^^^^^^^^^^^
  File "C:\Users\Merlyn\AppData\Local\Programs\Python\Python313\Lib\site-packages\discord\http.py", line 554, in ws_connect
    return await self.__session.ws_connect(url, **kwargs)
           ^^^^^^^^^^^^^^^^^^^^^^^^^^^^^^^^^^^^^^^^^^^^^^
  File "C:\Users\Merlyn\AppData\Local\Programs\Python\Python313\Lib\site-packages\aiohttp\client.py", line 1004, in _ws_connect
    resp = await self.request(
           ^^^^^^^^^^^^^^^^^^^
    ...<11 lines>...
    )
    ^
  File "C:\Users\Merlyn\AppData\Local\Programs\Python\Python313\Lib\site-packages\aiohttp\client.py", line 703, in _request
    conn = await self._connector.connect(
           ^^^^^^^^^^^^^^^^^^^^^^^^^^^^^^
        req, traces=traces, timeout=real_timeout
        ^^^^^^^^^^^^^^^^^^^^^^^^^^^^^^^^^^^^^^^^
    )
    ^
  File "C:\Users\Merlyn\AppData\Local\Programs\Python\Python313\Lib\site-packages\aiohttp\connector.py", line 548, in connect
    proto = await self._create_connection(req, traces, timeout)
            ^^^^^^^^^^^^^^^^^^^^^^^^^^^^^^^^^^^^^^^^^^^^^^^^^^^
  File "C:\Users\Merlyn\AppData\Local\Programs\Python\Python313\Lib\site-packages\aiohttp\connector.py", line 1056, in _create_connection
    _, proto = await self._create_direct_connection(req, traces, timeout)
               ^^^^^^^^^^^^^^^^^^^^^^^^^^^^^^^^^^^^^^^^^^^^^^^^^^^^^^^^^^
  File "C:\Users\Merlyn\AppData\Local\Programs\Python\Python313\Lib\site-packages\aiohttp\connector.py", line 1368, in _create_direct_connection
    raise ClientConnectorDNSError(req.connection_key, exc) from exc
aiohttp.client_exceptions.ClientConnectorDNSError: Cannot connect to host gateway-us-east1-c.discord.gg:443 ssl:default [getaddrinfo failed]
2025-03-10 18:07:26,214 - ERROR - Attempting a reconnect in 28.23s
Traceback (most recent call last):
  File "C:\Users\Merlyn\AppData\Local\Programs\Python\Python313\Lib\site-packages\aiohttp\connector.py", line 1362, in _create_direct_connection
    hosts = await self._resolve_host(host, port, traces=traces)
            ^^^^^^^^^^^^^^^^^^^^^^^^^^^^^^^^^^^^^^^^^^^^^^^^^^^
  File "C:\Users\Merlyn\AppData\Local\Programs\Python\Python313\Lib\site-packages\aiohttp\connector.py", line 995, in _resolve_host
    return await asyncio.shield(resolved_host_task)
           ^^^^^^^^^^^^^^^^^^^^^^^^^^^^^^^^^^^^^^^^
  File "C:\Users\Merlyn\AppData\Local\Programs\Python\Python313\Lib\site-packages\aiohttp\connector.py", line 1026, in _resolve_host_with_throttle
    addrs = await self._resolver.resolve(host, port, family=self._family)
            ^^^^^^^^^^^^^^^^^^^^^^^^^^^^^^^^^^^^^^^^^^^^^^^^^^^^^^^^^^^^^
  File "C:\Users\Merlyn\AppData\Local\Programs\Python\Python313\Lib\site-packages\aiohttp\resolver.py", line 36, in resolve
    infos = await self._loop.getaddrinfo(
            ^^^^^^^^^^^^^^^^^^^^^^^^^^^^^
    ...<5 lines>...
    )
    ^
  File "C:\Users\Merlyn\AppData\Local\Programs\Python\Python313\Lib\asyncio\base_events.py", line 934, in getaddrinfo
    return await self.run_in_executor(
           ^^^^^^^^^^^^^^^^^^^^^^^^^^^
        None, getaddr_func, host, port, family, type, proto, flags)
        ^^^^^^^^^^^^^^^^^^^^^^^^^^^^^^^^^^^^^^^^^^^^^^^^^^^^^^^^^^^
  File "C:\Users\Merlyn\AppData\Local\Programs\Python\Python313\Lib\concurrent\futures\thread.py", line 59, in run
    result = self.fn(*self.args, **self.kwargs)
  File "C:\Users\Merlyn\AppData\Local\Programs\Python\Python313\Lib\socket.py", line 975, in getaddrinfo
    for res in _socket.getaddrinfo(host, port, family, type, proto, flags):
               ~~~~~~~~~~~~~~~~~~~^^^^^^^^^^^^^^^^^^^^^^^^^^^^^^^^^^^^^^^^
socket.gaierror: [Errno 11001] getaddrinfo failed

The above exception was the direct cause of the following exception:

Traceback (most recent call last):
  File "C:\Users\Merlyn\AppData\Local\Programs\Python\Python313\Lib\site-packages\discord\client.py", line 701, in connect
    self.ws = await asyncio.wait_for(coro, timeout=60.0)
              ^^^^^^^^^^^^^^^^^^^^^^^^^^^^^^^^^^^^^^^^^^
  File "C:\Users\Merlyn\AppData\Local\Programs\Python\Python313\Lib\asyncio\tasks.py", line 507, in wait_for
    return await fut
           ^^^^^^^^^
  File "C:\Users\Merlyn\AppData\Local\Programs\Python\Python313\Lib\site-packages\discord\gateway.py", line 375, in from_client
    socket = await client.http.ws_connect(str(url))
             ^^^^^^^^^^^^^^^^^^^^^^^^^^^^^^^^^^^^^^
  File "C:\Users\Merlyn\AppData\Local\Programs\Python\Python313\Lib\site-packages\discord\http.py", line 554, in ws_connect
    return await self.__session.ws_connect(url, **kwargs)
           ^^^^^^^^^^^^^^^^^^^^^^^^^^^^^^^^^^^^^^^^^^^^^^
  File "C:\Users\Merlyn\AppData\Local\Programs\Python\Python313\Lib\site-packages\aiohttp\client.py", line 1004, in _ws_connect
    resp = await self.request(
           ^^^^^^^^^^^^^^^^^^^
    ...<11 lines>...
    )
    ^
  File "C:\Users\Merlyn\AppData\Local\Programs\Python\Python313\Lib\site-packages\aiohttp\client.py", line 703, in _request
    conn = await self._connector.connect(
           ^^^^^^^^^^^^^^^^^^^^^^^^^^^^^^
        req, traces=traces, timeout=real_timeout
        ^^^^^^^^^^^^^^^^^^^^^^^^^^^^^^^^^^^^^^^^
    )
    ^
  File "C:\Users\Merlyn\AppData\Local\Programs\Python\Python313\Lib\site-packages\aiohttp\connector.py", line 548, in connect
    proto = await self._create_connection(req, traces, timeout)
            ^^^^^^^^^^^^^^^^^^^^^^^^^^^^^^^^^^^^^^^^^^^^^^^^^^^
  File "C:\Users\Merlyn\AppData\Local\Programs\Python\Python313\Lib\site-packages\aiohttp\connector.py", line 1056, in _create_connection
    _, proto = await self._create_direct_connection(req, traces, timeout)
               ^^^^^^^^^^^^^^^^^^^^^^^^^^^^^^^^^^^^^^^^^^^^^^^^^^^^^^^^^^
  File "C:\Users\Merlyn\AppData\Local\Programs\Python\Python313\Lib\site-packages\aiohttp\connector.py", line 1368, in _create_direct_connection
    raise ClientConnectorDNSError(req.connection_key, exc) from exc
aiohttp.client_exceptions.ClientConnectorDNSError: Cannot connect to host gateway-us-east1-c.discord.gg:443 ssl:default [getaddrinfo failed]
2025-03-10 18:07:55,169 - INFO - Shard ID None session has been invalidated.
2025-03-10 18:08:00,604 - INFO - Shard ID None has connected to Gateway (Session ID: f0a20e0c5b2efdc08c55428466d41c57).
2025-03-10 18:08:02,654 - INFO - Logged in as anti-yappinator#0972 (ID: 1346984198023680121)
2025-03-10 18:08:02,657 - INFO - Connected to guild: Testing Server (ID: 1346987972121071739)
